File: DatingLeadS/Measurements-SZ/SZ-5/SZ5
Field (Oe)	Temperature (K)	Long Moment (EMU)
0.000000e+000	4.994539e+000	8.436439e-004
1.000000e+001	5.003374e+000	-2.123115e-002
2.000000e+001	5.003451e+000	-4.492306e-002
3.000000e+001	5.001347e+000	-7.289941e-002
4.000000e+001	4.995816e+000	-9.588885e-002
5.000000e+001	4.997474e+000	-1.220984e-001
6.000000e+001	4.996519e+000	-1.447497e-001
7.000000e+001	4.997711e+000	-1.719934e-001
8.000000e+001	4.997839e+000	-1.939912e-001
9.000000e+001	5.006866e+000	-2.182862e-001
1.000000e+002	5.001215e+000	-2.434576e-001
1.100000e+002	4.997942e+000	-2.632511e-001
1.200000e+002	4.999295e+000	-2.857992e-001
1.300000e+002	5.003275e+000	-3.038859e-001
1.400000e+002	5.000602e+000	-3.034362e-001
1.500000e+002	4.997199e+000	-2.870669e-001
1.600000e+002	5.000599e+000	-2.622380e-001
1.700000e+002	5.002288e+000	-2.495596e-001
1.800000e+002	5.000572e+000	-2.362119e-001
1.900000e+002	4.997378e+000	-2.276450e-001
2.000000e+002	5.000758e+000	-2.128196e-001
2.100000e+002	5.000418e+000	-1.968471e-001
2.200000e+002	4.997200e+000	-1.822784e-001
2.300000e+002	5.000522e+000	-1.683352e-001
2.400000e+002	5.000885e+000	-1.565001e-001
2.500000e+002	5.000546e+000	-1.470146e-001
2.600000e+002	5.000731e+000	-1.365530e-001
2.700000e+002	5.001667e+000	-1.283233e-001
2.800000e+002	5.001097e+000	-1.194032e-001
2.900000e+002	5.000678e+000	-1.116035e-001
3.000000e+002	5.001299e+000	-1.037752e-001
3.100000e+002	5.001589e+000	-9.603813e-002
3.200000e+002	4.997929e+000	-8.978495e-002
3.300000e+002	5.010573e+000	-7.917970e-002
3.400000e+002	5.004217e+000	-7.256521e-002
3.500000e+002	4.997096e+000	-6.641327e-002
3.600000e+002	5.000264e+000	-5.880783e-002
3.700000e+002	4.999948e+000	-5.159726e-002
3.800000e+002	5.000678e+000	-4.497969e-002
3.900000e+002	5.001352e+000	-3.657309e-002
4.000000e+002	5.010388e+000	-2.756431e-002
4.100000e+002	5.005282e+000	-2.121300e-002
4.200000e+002	5.010184e+000	-1.047302e-002
4.300000e+002	5.002126e+000	-2.390623e-003
4.400000e+002	4.993810e+000	-2.785702e-004
4.500000e+002	5.002466e+000	-1.752478e-004
4.600000e+002	4.997709e+000	1.907161e-005
4.700000e+002	4.996027e+000	3.197126e-005
4.800000e+002	5.000129e+000	2.102698e-005
4.900000e+002	5.004061e+000	-1.661690e-005
5.000000e+002	5.002181e+000	-1.419454e-005
5.100000e+002	4.998527e+000	-2.599061e-006
5.200000e+002	4.998987e+000	1.814808e-005
5.300000e+002	5.000160e+000	2.682297e-005
5.400000e+002	5.010395e+000	3.400611e-005
5.500000e+002	5.000080e+000	3.711681e-005
5.600000e+002	5.005828e+000	4.358456e-005
5.700000e+002	5.000207e+000	4.535277e-005
5.800000e+002	4.999768e+000	4.893617e-005
5.900000e+002	4.996163e+000	5.209187e-005
6.000000e+002	4.999591e+000	5.492750e-005
6.000000e+002	5.005621e+000	5.553231e-005
6.200000e+002	5.001971e+000	5.953354e-005
6.400000e+002	5.000107e+000	6.447696e-005
6.600000e+002	4.999689e+000	6.873206e-005
6.800000e+002	5.000551e+000	7.231337e-005
7.000000e+002	5.003172e+000	7.616446e-005
7.200000e+002	4.999456e+000	7.935285e-005
7.400000e+002	5.002600e+000	8.258130e-005
7.600000e+002	5.003876e+000	8.597385e-005
7.800000e+002	5.000836e+000	8.886329e-005
8.000000e+002	5.000813e+000	9.187269e-005
0.000000e+000	4.998438e+000	7.017440e-005
1.000000e+001	5.006495e+000	-4.671530e-003
2.000000e+001	4.997763e+000	-1.009412e-002
3.000000e+001	4.996902e+000	-1.659544e-002
4.000000e+001	5.003925e+000	-2.196024e-002
5.000000e+001	4.997634e+000	-2.721042e-002
6.000000e+001	4.997080e+000	-3.325902e-002
7.000000e+001	4.997574e+000	-3.956183e-002
8.000000e+001	5.000306e+000	-4.465581e-002
9.000000e+001	4.996830e+000	-4.966189e-002
1.000000e+002	5.008375e+000	-5.529768e-002
1.100000e+002	5.003225e+000	-6.090540e-002
1.200000e+002	4.999685e+000	-6.631830e-002
1.300000e+002	5.000385e+000	-7.102565e-002
1.400000e+002	5.000988e+000	-7.647392e-002
1.500000e+002	4.997480e+000	-8.096243e-002
1.600000e+002	5.000988e+000	-8.578731e-002
1.700000e+002	5.000231e+000	-9.084775e-002
1.800000e+002	5.000232e+000	-9.501408e-002
1.900000e+002	5.000726e+000	-9.970659e-002
2.000000e+002	5.002031e+000	-1.045318e-001
2.100000e+002	5.008169e+000	-1.084411e-001
2.200000e+002	5.003382e+000	-1.128849e-001
2.300000e+002	5.000491e+000	-1.166964e-001
2.400000e+002	5.000259e+000	-1.212494e-001
2.500000e+002	4.999505e+000	-1.253418e-001
2.600000e+002	5.000129e+000	-1.289656e-001
2.700000e+002	4.999895e+000	-1.332452e-001
2.800000e+002	4.999818e+000	-1.370624e-001
2.900000e+002	4.996705e+000	-1.402868e-001
3.000000e+002	5.000079e+000	-1.440038e-001
3.100000e+002	4.999403e+000	-1.468624e-001
3.200000e+002	4.999975e+000	-1.499062e-001
3.300000e+002	4.996578e+000	-1.522605e-001
3.400000e+002	4.996006e+000	-1.546647e-001
3.500000e+002	4.999557e+000	-1.562658e-001
3.600000e+002	4.995693e+000	-1.572735e-001
3.700000e+002	4.999327e+000	-1.572165e-001
3.800000e+002	4.999898e+000	-1.551165e-001
3.900000e+002	4.995383e+000	-1.504308e-001
4.000000e+002	4.999015e+000	-1.372060e-001
4.100000e+002	4.999116e+000	-1.104375e-001
4.200000e+002	4.996242e+000	-7.368231e-002
4.300000e+002	4.993346e+000	-1.685221e-002
4.400000e+002	5.009862e+000	-8.105411e-005
4.500000e+002	5.005771e+000	-5.844870e-005
4.600000e+002	5.001476e+000	-4.699611e-005
4.700000e+002	4.998388e+000	-3.067790e-005
4.800000e+002	4.999665e+000	-1.518880e-005
4.900000e+002	4.996553e+000	-3.910988e-007
5.000000e+002	4.996185e+000	9.752628e-006
5.100000e+002	4.999275e+000	1.714429e-005
5.200000e+002	4.999455e+000	2.390027e-005
5.300000e+002	4.999928e+000	2.906247e-005
5.400000e+002	5.000031e+000	3.463085e-005
5.500000e+002	5.000521e+000	3.832213e-005
5.600000e+002	4.999198e+000	4.198795e-005
5.700000e+002	4.998987e+000	4.508897e-005
5.800000e+002	4.995616e+000	4.809835e-005
5.900000e+002	4.999118e+000	5.079569e-005
6.000000e+002	4.995435e+000	5.314164e-005
6.000000e+002	5.007103e+000	5.325937e-005
6.200000e+002	5.011515e+000	5.760285e-005
6.400000e+002	5.002239e+000	6.140543e-005
6.600000e+002	4.999896e+000	6.473729e-005
6.800000e+002	4.995725e+000	6.833625e-005
7.000000e+002	4.999795e+000	7.102149e-005