File: DatingLeadS/Input/SZ4
Field (Oe)	Temperature (K)	Long Moment (EMU)
0.000000e+000	4.997182e+000	3.123761e-003
1.000000e+001	5.004493e+000	-3.409911e-002
2.000000e+001	4.998042e+000	-7.110415e-002
3.000000e+001	4.999651e+000	-1.147624e-001
4.000000e+001	5.001709e+000	-1.498971e-001
5.000000e+001	4.996179e+000	-1.855610e-001
6.000000e+001	4.999051e+000	-2.263927e-001
7.000000e+001	4.999502e+000	-2.613392e-001
8.000000e+001	5.000523e+000	-3.035938e-001
9.000000e+001	4.997486e+000	-3.377459e-001
1.000000e+002	5.001410e+000	-3.772310e-001
1.100000e+002	5.000936e+000	-4.169321e-001
1.200000e+002	4.998320e+000	-4.502546e-001
1.300000e+002	5.001513e+000	-4.877582e-001
1.400000e+002	5.000891e+000	-5.262222e-001
1.500000e+002	5.003621e+000	-5.641689e-001
1.600000e+002	5.010726e+000	-5.950823e-001
1.700000e+002	5.010878e+000	-6.361659e-001
1.800000e+002	4.988770e+000	-6.656764e-001
1.900000e+002	5.000185e+000	-6.948735e-001
2.000000e+002	4.998186e+000	-7.259314e-001
2.100000e+002	5.000731e+000	-7.567213e-001
2.200000e+002	5.001278e+000	-7.825544e-001
2.300000e+002	5.000836e+000	-8.009365e-001
2.400000e+002	5.000087e+000	-8.053187e-001
2.500000e+002	5.000629e+000	-7.822939e-001
2.600000e+002	4.998861e+000	-7.467699e-001
2.700000e+002	4.998235e+000	-6.974841e-001
2.800000e+002	4.998158e+000	-6.556150e-001
2.900000e+002	4.997586e+000	-6.046215e-001
3.000000e+002	4.998470e+000	-5.555559e-001
3.100000e+002	4.998601e+000	-5.151091e-001
3.200000e+002	4.998156e+000	-4.615759e-001
3.300000e+002	4.994917e+000	-4.189419e-001
3.400000e+002	4.998339e+000	-3.741791e-001
3.500000e+002	4.997666e+000	-3.283068e-001
3.600000e+002	4.994503e+000	-2.921379e-001
3.700000e+002	4.991326e+000	-2.340201e-001
3.800000e+002	5.011575e+000	-2.018407e-001
3.900000e+002	5.005027e+000	-1.731578e-001
4.000000e+002	5.001201e+000	-1.327628e-001
4.100000e+002	4.996973e+000	-9.847725e-002
4.200000e+002	5.011150e+000	-5.026754e-002
4.300000e+002	5.001324e+000	-6.327493e-003
4.400000e+002	4.992775e+000	6.859086e-005
4.500000e+002	5.000775e+000	-5.458145e-005
4.600000e+002	4.999484e+000	2.066860e-004
4.700000e+002	5.000759e+000	2.870738e-004
4.800000e+002	5.000812e+000	3.586457e-004
4.900000e+002	5.000943e+000	4.378610e-004
5.000000e+002	5.001409e+000	5.017428e-004
5.100000e+002	5.000347e+000	5.599712e-004
5.200000e+002	5.005213e+000	6.265279e-004
5.300000e+002	5.002087e+000	6.558569e-004
5.400000e+002	5.000497e+000	7.012400e-004
5.500000e+002	5.001229e+000	7.413819e-004
5.600000e+002	5.001277e+000	7.756283e-004
5.700000e+002	5.001019e+000	8.135389e-004
5.800000e+002	5.001100e+000	8.436120e-004
5.900000e+002	5.000737e+000	8.738909e-004
6.000000e+002	5.000003e+000	9.063508e-004
6.000000e+002	5.005969e+000	9.113877e-004
6.200000e+002	5.010721e+000	9.697734e-004
6.400000e+002	5.003124e+000	1.026007e-003
6.600000e+002	5.000242e+000	1.084039e-003
6.800000e+002	4.999878e+000	1.138497e-003
7.000000e+002	4.997179e+000	1.188134e-003
7.200000e+002	5.000134e+000	1.247781e-003
7.400000e+002	5.000478e+000	1.301844e-003
7.600000e+002	5.001595e+000	1.354075e-003
7.800000e+002	5.000397e+000	1.407315e-003
8.000000e+002	5.000916e+000	1.459001e-003
0.000000e+000	5.007723e+000	2.540970e-003
1.000000e+001	5.002911e+000	-1.539263e-002
2.000000e+001	4.997316e+000	-3.604854e-002
3.000000e+001	5.005637e+000	-5.621101e-002
4.000000e+001	4.998432e+000	-7.834822e-002
5.000000e+001	4.997708e+000	-1.021794e-001
6.000000e+001	4.997940e+000	-1.220615e-001
7.000000e+001	4.997473e+000	-1.417958e-001
8.000000e+001	4.997369e+000	-1.636775e-001
9.000000e+001	4.997499e+000	-1.863855e-001
1.000000e+002	4.996434e+000	-2.056053e-001
1.100000e+002	4.997856e+000	-2.269602e-001
1.200000e+002	5.000485e+000	-2.487789e-001
1.300000e+002	4.998930e+000	-2.664267e-001
1.400000e+002	4.994438e+000	-2.861991e-001
1.500000e+002	4.996746e+000	-3.071844e-001
1.600000e+002	4.996979e+000	-3.290669e-001
1.700000e+002	4.997369e+000	-3.468140e-001
1.800000e+002	4.996825e+000	-3.671091e-001
1.900000e+002	4.997032e+000	-3.881529e-001
2.000000e+002	4.998229e+000	-4.054719e-001
2.100000e+002	4.997942e+000	-4.248620e-001
2.200000e+002	4.994517e+000	-4.418539e-001
2.300000e+002	4.997501e+000	-4.612847e-001
2.400000e+002	4.997655e+000	-4.794186e-001
2.500000e+002	4.997892e+000	-4.982300e-001
2.600000e+002	4.997163e+000	-5.129669e-001
2.700000e+002	5.006783e+000	-5.325587e-001
2.800000e+002	4.997502e+000	-5.484690e-001
2.900000e+002	4.994186e+000	-5.632025e-001
3.000000e+002	4.995764e+000	-5.744665e-001
3.100000e+002	4.998073e+000	-5.848932e-001
3.200000e+002	5.002128e+000	-5.918311e-001
3.300000e+002	4.999270e+000	-5.925468e-001
3.400000e+002	4.999143e+000	-5.820554e-001
3.500000e+002	4.999558e+000	-5.485367e-001
3.600000e+002	5.001953e+000	-4.997980e-001
3.700000e+002	5.000627e+000	-4.408327e-001
3.800000e+002	4.996157e+000	-3.859863e-001
3.900000e+002	4.999325e+000	-3.152029e-001
4.000000e+002	4.996240e+000	-2.583475e-001
4.100000e+002	4.996235e+000	-1.866896e-001
4.200000e+002	4.999558e+000	-1.094094e-001
4.300000e+002	5.001349e+000	-2.728851e-002
4.400000e+002	5.008400e+000	1.431014e-004
4.500000e+002	5.000543e+000	2.611606e-004
4.600000e+002	4.996825e+000	3.605133e-004
4.700000e+002	4.994699e+000	4.891528e-004
4.800000e+002	4.995010e+000	5.843022e-004
4.900000e+002	4.995270e+000	6.538053e-004
5.000000e+002	4.997478e+000	7.272128e-004
5.100000e+002	4.994336e+000	7.791778e-004
5.200000e+002	4.997189e+000	8.363534e-004
5.300000e+002	4.997192e+000	8.890908e-004
5.400000e+002	4.998103e+000	9.317445e-004
5.500000e+002	5.007472e+000	9.780604e-004
5.600000e+002	4.997657e+000	1.011035e-003
5.700000e+002	4.997790e+000	1.054552e-003
5.800000e+002	4.997347e+000	1.089564e-003
5.900000e+002	4.997894e+000	1.129715e-003
6.000000e+002	4.996957e+000	1.162832e-003
6.000000e+002	5.009708e+000	1.166943e-003
6.200000e+002	5.004344e+000	1.233786e-003
6.400000e+002	4.997323e+000	1.302460e-003
6.600000e+002	4.997089e+000	1.370415e-003
6.800000e+002	4.998622e+000	1.434239e-003
7.000000e+002	5.000177e+000	1.499552e-003
7.200000e+002	4.997922e+000	1.561221e-003
7.400000e+002	4.998571e+000	1.623641e-003