File: DatingLeadS/Input/SZ6
Field (Oe)	Temperature (K)	Long Moment (EMU)
0.000000e+000	5.001550e+000	5.580974e-004
1.000000e+001	5.003004e+000	-2.413530e-002
2.000000e+001	5.001345e+000	-5.441373e-002
3.000000e+001	4.996068e+000	-9.107128e-002
4.000000e+001	5.002821e+000	-1.225484e-001
5.000000e+001	4.996977e+000	-1.563480e-001
6.000000e+001	4.996484e+000	-1.866131e-001
7.000000e+001	4.995863e+000	-2.165630e-001
8.000000e+001	4.996274e+000	-2.516041e-001
9.000000e+001	4.995471e+000	-2.800788e-001
1.000000e+002	4.998976e+000	-3.124360e-001
1.100000e+002	4.998175e+000	-3.456288e-001
1.200000e+002	4.995193e+000	-3.728555e-001
1.300000e+002	4.997763e+000	-4.088241e-001
1.400000e+002	4.998853e+000	-4.347883e-001
1.500000e+002	4.994493e+000	-4.604633e-001
1.600000e+002	4.997894e+000	-4.879023e-001
1.700000e+002	4.997943e+000	-5.139009e-001
1.800000e+002	4.999580e+000	-5.301635e-001
1.900000e+002	4.998230e+000	-5.440224e-001
2.000000e+002	4.997477e+000	-5.434368e-001
2.100000e+002	4.998334e+000	-5.251861e-001
2.200000e+002	4.997893e+000	-4.710262e-001
2.300000e+002	4.998413e+000	-4.197625e-001
2.400000e+002	5.000022e+000	-3.829029e-001
2.500000e+002	4.998336e+000	-3.484349e-001
2.600000e+002	4.997140e+000	-3.239759e-001
2.700000e+002	4.997606e+000	-2.985188e-001
2.800000e+002	4.998126e+000	-2.787029e-001
2.900000e+002	4.997946e+000	-2.581581e-001
3.000000e+002	4.998543e+000	-2.427835e-001
3.100000e+002	4.998207e+000	-2.278625e-001
3.200000e+002	4.998335e+000	-2.113170e-001
3.300000e+002	4.998495e+000	-1.943897e-001
3.400000e+002	4.996858e+000	-1.796481e-001
3.500000e+002	4.997712e+000	-1.622826e-001
3.600000e+002	4.998075e+000	-1.432566e-001
3.700000e+002	4.997558e+000	-1.269396e-001
3.800000e+002	4.992694e+000	-1.034923e-001
3.900000e+002	4.998148e+000	-8.857648e-002
4.000000e+002	4.995551e+000	-6.709417e-002
4.100000e+002	4.994025e+000	-4.897917e-002
4.200000e+002	5.005152e+000	-2.365356e-002
4.300000e+002	4.999574e+000	-3.134544e-004
4.400000e+002	4.997602e+000	-1.904494e-004
4.500000e+002	4.995708e+000	-1.412686e-004
4.600000e+002	4.995502e+000	-1.080229e-004
4.700000e+002	4.995008e+000	-8.573510e-005
4.800000e+002	5.002337e+000	-6.212108e-005
4.900000e+002	4.994257e+000	-5.175183e-005
5.000000e+002	4.994514e+000	-3.723948e-005
5.100000e+002	4.995655e+000	-2.735189e-005
5.200000e+002	4.995944e+000	-1.899732e-005
5.300000e+002	5.005688e+000	-9.612546e-006
5.400000e+002	4.997188e+000	-2.642809e-006
5.500000e+002	5.004098e+000	1.097935e-005
5.600000e+002	5.005643e+000	1.444669e-005
5.700000e+002	4.996565e+000	1.777295e-005
5.800000e+002	5.006183e+000	2.375390e-005
5.900000e+002	4.997525e+000	2.648179e-005
6.000000e+002	4.993816e+000	2.958137e-005
6.000000e+002	5.006315e+000	3.070378e-005
6.200000e+002	5.004546e+000	3.794270e-005
6.400000e+002	4.996852e+000	4.305295e-005
6.600000e+002	4.996954e+000	4.897806e-005
6.800000e+002	4.991615e+000	5.379020e-005
7.000000e+002	4.994670e+000	5.843100e-005
0.000000e+000	4.996464e+000	1.298003e-004
1.000000e+001	5.007070e+000	-8.808263e-003
2.000000e+001	5.004958e+000	-2.474444e-002
3.000000e+001	5.000251e+000	-3.798137e-002
4.000000e+001	4.997808e+000	-5.097525e-002
5.000000e+001	5.000862e+000	-6.564732e-002
6.000000e+001	5.002228e+000	-7.843129e-002
7.000000e+001	4.996902e+000	-9.387920e-002
8.000000e+001	4.996721e+000	-1.065183e-001
9.000000e+001	4.994802e+000	-1.188755e-001
1.000000e+002	4.995836e+000	-1.352095e-001
1.100000e+002	4.995603e+000	-1.468082e-001
1.200000e+002	4.996693e+000	-1.600491e-001
1.300000e+002	4.996174e+000	-1.714719e-001
1.400000e+002	4.996305e+000	-1.850225e-001
1.500000e+002	4.994932e+000	-1.960132e-001
1.600000e+002	4.994048e+000	-2.080719e-001
1.700000e+002	5.002128e+000	-2.202875e-001
1.800000e+002	4.997866e+000	-2.319652e-001
1.900000e+002	4.995553e+000	-2.420411e-001
2.000000e+002	4.996123e+000	-2.539852e-001
2.100000e+002	4.997004e+000	-2.648365e-001
2.200000e+002	4.995447e+000	-2.741978e-001
2.300000e+002	4.995318e+000	-2.848346e-001
2.400000e+002	4.995500e+000	-2.938334e-001
2.500000e+002	4.995526e+000	-3.032911e-001
2.600000e+002	4.995943e+000	-3.125559e-001
2.700000e+002	4.997084e+000	-3.196306e-001
2.800000e+002	4.998407e+000	-3.256903e-001
2.900000e+002	4.995240e+000	-3.316339e-001
3.000000e+002	4.995291e+000	-3.362226e-001
3.100000e+002	4.995967e+000	-3.387147e-001
3.200000e+002	4.995967e+000	-3.400373e-001
3.300000e+002	4.996459e+000	-3.385646e-001
3.400000e+002	4.994206e+000	-3.346151e-001
3.500000e+002	4.995734e+000	-3.247149e-001
3.600000e+002	4.995602e+000	-3.055702e-001
3.700000e+002	4.995499e+000	-2.839552e-001
3.800000e+002	4.995528e+000	-2.560567e-001
3.900000e+002	4.995655e+000	-2.186264e-001
4.000000e+002	4.995577e+000	-1.725144e-001
4.100000e+002	4.996123e+000	-1.231611e-001
4.200000e+002	5.007514e+000	-6.381485e-002
4.300000e+002	5.006106e+000	-4.648798e-003
4.400000e+002	5.004755e+000	-1.278763e-004
4.500000e+002	4.996770e+000	-1.074152e-004
4.600000e+002	5.002234e+000	-7.603707e-005
4.700000e+002	4.996799e+000	-6.285463e-005
4.800000e+002	4.995421e+000	-4.626728e-005
4.900000e+002	4.994204e+000	-3.481426e-005
5.000000e+002	4.995811e+000	-2.297717e-005
5.100000e+002	4.996150e+000	-1.482901e-005
5.200000e+002	4.996434e+000	-5.577790e-006
5.300000e+002	4.996460e+000	3.980413e-006
5.400000e+002	4.993659e+000	8.200961e-006
5.500000e+002	4.997341e+000	1.335454e-005
5.600000e+002	4.993737e+000	1.744143e-005
5.700000e+002	4.995965e+000	2.208492e-005
5.800000e+002	4.995420e+000	2.636197e-005
5.900000e+002	4.995891e+000	2.972201e-005
6.000000e+002	4.999263e+000	3.312006e-005
6.000000e+002	5.005792e+000	3.372235e-005
6.200000e+002	4.998095e+000	3.934155e-005
6.400000e+002	4.995449e+000	4.530192e-005
6.600000e+002	4.995473e+000	4.968680e-005