File: DatingLeadS/Measurements-SZ/SZ-1/SZ1
Field (Oe)	Temperature (K)	Long Moment (EMU)
0.000000e+000	4.998145e+000	4.416396e-005
5.000000e+000	5.005218e+000	-7.716459e-003
1.000000e+001	5.006914e+000	-3.299665e-002
1.500000e+001	4.998927e+000	-5.412551e-002
2.000000e+001	4.999111e+000	-7.883193e-002
2.500000e+001	4.996180e+000	-9.982023e-002
3.000000e+001	5.005532e+000	-1.248693e-001
3.500000e+001	5.000673e+000	-1.539163e-001
4.000000e+001	4.995945e+000	-1.744806e-001
4.500000e+001	4.995842e+000	-1.978974e-001
5.000000e+001	4.996179e+000	-2.189424e-001
5.500000e+001	4.995453e+000	-2.421706e-001
6.000000e+001	4.995791e+000	-2.725380e-001
6.500000e+001	4.995868e+000	-2.933344e-001
7.000000e+001	4.995062e+000	-3.167960e-001
7.500000e+001	4.995558e+000	-3.460772e-001
8.000000e+001	4.995167e+000	-3.664155e-001
8.500000e+001	4.993541e+000	-3.900056e-001
9.000000e+001	4.996409e+000	-4.180402e-001
9.500000e+001	4.992731e+000	-4.317532e-001
1.000000e+002	4.994907e+000	-4.611283e-001
1.200000e+002	4.997425e+000	-5.504836e-001
1.400000e+002	5.000257e+000	-6.462572e-001
1.600000e+002	5.004288e+000	-7.323565e-001
1.800000e+002	5.002025e+000	-8.105228e-001
2.000000e+002	4.997659e+000	-8.864433e-001
2.200000e+002	4.999162e+000	-9.571515e-001
2.400000e+002	5.000489e+000	-1.006815e+000
2.600000e+002	4.998778e+000	-9.852329e-001
2.800000e+002	4.999275e+000	-9.102799e-001
3.000000e+002	4.998048e+000	-8.249658e-001
3.200000e+002	5.001270e+000	-7.212725e-001
3.400000e+002	4.998935e+000	-6.210356e-001
3.600000e+002	5.000940e+000	-4.946324e-001
3.800000e+002	5.002860e+000	-3.337966e-001
4.000000e+002	5.002155e+000	-1.884073e-001
4.200000e+002	5.004106e+000	-6.820797e-002
4.400000e+002	5.008349e+000	-1.653808e-003
4.600000e+002	5.008819e+000	-5.536040e-004
4.800000e+002	5.002231e+000	-4.665525e-004
5.000000e+002	4.997347e+000	-3.808952e-004
5.200000e+002	5.009732e+000	-2.364281e-004
5.400000e+002	5.000126e+000	-1.783390e-004
5.600000e+002	4.997086e+000	-1.241447e-004
5.800000e+002	4.997505e+000	-8.481550e-005
6.000000e+002	5.008169e+000	-4.791156e-005
6.200000e+002	5.004369e+000	-2.075395e-005
6.400000e+002	5.002336e+000	-6.027916e-006
6.600000e+002	4.997739e+000	1.237357e-005
6.800000e+002	4.997163e+000	2.853749e-005
7.000000e+002	4.997605e+000	4.351599e-005
7.200000e+002	4.997838e+000	5.605651e-005
7.400000e+002	4.997086e+000	6.740885e-005
7.600000e+002	4.997214e+000	7.865048e-005
7.800000e+002	4.996594e+000	8.884340e-005
8.000000e+002	4.997400e+000	9.891654e-005
8.200000e+002	4.997816e+000	1.071829e-004
8.400000e+002	5.009447e+000	1.168044e-004
8.600000e+002	4.994822e+000	1.246007e-004
8.800000e+002	5.001449e+000	1.320710e-004
9.000000e+002	5.009837e+000	1.390925e-004
9.200000e+002	5.000442e+000	1.478613e-004
9.400000e+002	4.997475e+000	1.525212e-004
9.600000e+002	4.997244e+000	1.591162e-004
9.800000e+002	4.998746e+000	1.668600e-004
1.000000e+003	4.997139e+000	1.716687e-004
0.000000e+000	5.002525e+000	2.784557e-003
5.000000e+000	5.003395e+000	-8.119862e-003
1.000000e+001	5.006681e+000	-2.321512e-002
1.500000e+001	4.994825e+000	-3.975772e-002
2.000000e+001	5.006524e+000	-6.038655e-002
2.500000e+001	4.994545e+000	-7.013406e-002
3.000000e+001	4.994179e+000	-9.101938e-002
3.500000e+001	4.993971e+000	-1.054275e-001
4.000000e+001	4.994928e+000	-1.218275e-001
4.500000e+001	4.994387e+000	-1.361392e-001
5.000000e+001	4.994205e+000	-1.564108e-001
5.500000e+001	4.995476e+000	-1.728766e-001
6.000000e+001	4.996074e+000	-1.869364e-001
6.500000e+001	4.994750e+000	-2.071714e-001
7.000000e+001	5.000116e+000	-2.236250e-001
7.500000e+001	4.997551e+000	-2.371642e-001
8.000000e+001	4.992857e+000	-2.528544e-001
8.500000e+001	4.994359e+000	-2.725322e-001
9.000000e+001	4.993272e+000	-2.829064e-001
9.500000e+001	4.994958e+000	-3.026682e-001
1.000000e+002	4.992677e+000	-3.168396e-001
1.200000e+002	4.998487e+000	-3.853024e-001
1.400000e+002	4.997890e+000	-4.488707e-001
1.600000e+002	5.000486e+000	-5.143808e-001
1.800000e+002	5.007123e+000	-5.784782e-001
2.000000e+002	5.004235e+000	-6.371510e-001
2.200000e+002	5.000047e+000	-6.913618e-001
2.400000e+002	4.999632e+000	-7.432351e-001
2.600000e+002	5.000955e+000	-7.940141e-001
2.800000e+002	4.998957e+000	-8.347326e-001
3.000000e+002	4.998310e+000	-8.661467e-001
3.200000e+002	4.998229e+000	-8.371643e-001
3.400000e+002	4.998621e+000	-7.301893e-001
3.600000e+002	4.998648e+000	-5.941919e-001
3.800000e+002	5.008616e+000	-4.386452e-001
4.000000e+002	5.003198e+000	-2.992833e-001
4.200000e+002	5.009001e+000	-1.125372e-001
4.400000e+002	5.008841e+000	-6.750193e-004
4.600000e+002	5.001838e+000	-4.825900e-004
4.800000e+002	4.998074e+000	-3.363948e-004
5.000000e+002	5.007489e+000	-2.182679e-004
5.200000e+002	4.999186e+000	-1.633355e-004
5.400000e+002	4.997448e+000	-1.133054e-004
5.600000e+002	4.998593e+000	-7.584064e-005
5.800000e+002	5.007539e+000	-4.112931e-005
6.000000e+002	4.999187e+000	-2.272748e-005
6.200000e+002	4.997710e+000	4.803658e-007
6.400000e+002	5.000825e+000	1.691881e-005
6.600000e+002	5.001191e+000	3.117852e-005
6.800000e+002	4.999036e+000	4.299398e-005
7.000000e+002	5.001297e+000	5.589590e-005
7.200000e+002	4.994300e+000	6.485086e-005